[2025-06-06T19:12:00.060+0000] {taskinstance.py:1956} INFO - Dependencies all met for dep_context=non-requeueable deps ti=<TaskInstance: parallel_dag.get_users manual__2025-06-06T19:10:50.997723+00:00 [queued]>
[2025-06-06T19:12:00.072+0000] {taskinstance.py:1956} INFO - Dependencies all met for dep_context=requeueable deps ti=<TaskInstance: parallel_dag.get_users manual__2025-06-06T19:10:50.997723+00:00 [queued]>
[2025-06-06T19:12:00.073+0000] {taskinstance.py:2170} INFO - Starting attempt 2 of 5
[2025-06-06T19:12:00.088+0000] {taskinstance.py:2191} INFO - Executing <Task(PythonOperator): get_users> on 2025-06-06 19:10:50.997723+00:00
[2025-06-06T19:12:00.095+0000] {standard_task_runner.py:60} INFO - Started process 8684 to run task
[2025-06-06T19:12:00.105+0000] {standard_task_runner.py:87} INFO - Running: ['***', 'tasks', 'run', 'parallel_dag', 'get_users', 'manual__2025-06-06T19:10:50.997723+00:00', '--job-id', '341', '--raw', '--subdir', 'DAGS_FOLDER/parallel_dag.py', '--cfg-path', '/tmp/tmpshdw21eo']
[2025-06-06T19:12:00.107+0000] {standard_task_runner.py:88} INFO - Job 341: Subtask get_users
[2025-06-06T19:12:00.189+0000] {task_command.py:423} INFO - Running <TaskInstance: parallel_dag.get_users manual__2025-06-06T19:10:50.997723+00:00 [running]> on host f00d934cb96d
[2025-06-06T19:12:00.302+0000] {taskinstance.py:2480} INFO - Exporting env vars: AIRFLOW_CTX_DAG_OWNER='Pavan Kumar Kodavali' AIRFLOW_CTX_DAG_ID='parallel_dag' AIRFLOW_CTX_TASK_ID='get_users' AIRFLOW_CTX_EXECUTION_DATE='2025-06-06T19:10:50.997723+00:00' AIRFLOW_CTX_TRY_NUMBER='2' AIRFLOW_CTX_DAG_RUN_ID='manual__2025-06-06T19:10:50.997723+00:00'
[2025-06-06T19:12:00.305+0000] {taskinstance.py:2698} ERROR - Task failed with exception
Traceback (most recent call last):
  File "/home/airflow/.local/lib/python3.8/site-packages/airflow/models/taskinstance.py", line 433, in _execute_task
    result = execute_callable(context=context, **execute_callable_kwargs)
  File "/home/airflow/.local/lib/python3.8/site-packages/airflow/operators/python.py", line 199, in execute
    return_value = self.execute_callable()
  File "/home/airflow/.local/lib/python3.8/site-packages/airflow/operators/python.py", line 216, in execute_callable
    return self.python_callable(*self.op_args, **self.op_kwargs)
TypeError: get() missing 1 required positional argument: 'url'
[2025-06-06T19:12:00.326+0000] {taskinstance.py:1138} INFO - Marking task as UP_FOR_RETRY. dag_id=parallel_dag, task_id=get_users, execution_date=20250606T191050, start_date=20250606T191200, end_date=20250606T191200
[2025-06-06T19:12:00.346+0000] {standard_task_runner.py:107} ERROR - Failed to execute job 341 for task get_users (get() missing 1 required positional argument: 'url'; 8684)
[2025-06-06T19:12:00.362+0000] {local_task_job_runner.py:234} INFO - Task exited with return code 1
[2025-06-06T19:12:00.392+0000] {taskinstance.py:3280} INFO - 0 downstream tasks scheduled from follow-on schedule check
