[2025-06-06T19:12:06.595+0000] {taskinstance.py:1956} INFO - Dependencies all met for dep_context=non-requeueable deps ti=<TaskInstance: parallel_dag.get_users scheduled__2025-06-05T00:00:00+00:00 [queued]>
[2025-06-06T19:12:06.607+0000] {taskinstance.py:1956} INFO - Dependencies all met for dep_context=requeueable deps ti=<TaskInstance: parallel_dag.get_users scheduled__2025-06-05T00:00:00+00:00 [queued]>
[2025-06-06T19:12:06.608+0000] {taskinstance.py:2170} INFO - Starting attempt 2 of 5
[2025-06-06T19:12:06.629+0000] {taskinstance.py:2191} INFO - Executing <Task(PythonOperator): get_users> on 2025-06-05 00:00:00+00:00
[2025-06-06T19:12:06.637+0000] {standard_task_runner.py:60} INFO - Started process 8790 to run task
[2025-06-06T19:12:06.642+0000] {standard_task_runner.py:87} INFO - Running: ['***', 'tasks', 'run', 'parallel_dag', 'get_users', 'scheduled__2025-06-05T00:00:00+00:00', '--job-id', '342', '--raw', '--subdir', 'DAGS_FOLDER/parallel_dag.py', '--cfg-path', '/tmp/tmp3i90r_2s']
[2025-06-06T19:12:06.644+0000] {standard_task_runner.py:88} INFO - Job 342: Subtask get_users
[2025-06-06T19:12:06.760+0000] {task_command.py:423} INFO - Running <TaskInstance: parallel_dag.get_users scheduled__2025-06-05T00:00:00+00:00 [running]> on host f00d934cb96d
[2025-06-06T19:12:06.891+0000] {taskinstance.py:2480} INFO - Exporting env vars: AIRFLOW_CTX_DAG_OWNER='Pavan Kumar Kodavali' AIRFLOW_CTX_DAG_ID='parallel_dag' AIRFLOW_CTX_TASK_ID='get_users' AIRFLOW_CTX_EXECUTION_DATE='2025-06-05T00:00:00+00:00' AIRFLOW_CTX_TRY_NUMBER='2' AIRFLOW_CTX_DAG_RUN_ID='scheduled__2025-06-05T00:00:00+00:00'
[2025-06-06T19:12:06.893+0000] {taskinstance.py:2698} ERROR - Task failed with exception
Traceback (most recent call last):
  File "/home/airflow/.local/lib/python3.8/site-packages/airflow/models/taskinstance.py", line 433, in _execute_task
    result = execute_callable(context=context, **execute_callable_kwargs)
  File "/home/airflow/.local/lib/python3.8/site-packages/airflow/operators/python.py", line 199, in execute
    return_value = self.execute_callable()
  File "/home/airflow/.local/lib/python3.8/site-packages/airflow/operators/python.py", line 216, in execute_callable
    return self.python_callable(*self.op_args, **self.op_kwargs)
TypeError: get() missing 1 required positional argument: 'url'
[2025-06-06T19:12:06.908+0000] {taskinstance.py:1138} INFO - Marking task as UP_FOR_RETRY. dag_id=parallel_dag, task_id=get_users, execution_date=20250605T000000, start_date=20250606T191206, end_date=20250606T191206
[2025-06-06T19:12:06.935+0000] {standard_task_runner.py:107} ERROR - Failed to execute job 342 for task get_users (get() missing 1 required positional argument: 'url'; 8790)
[2025-06-06T19:12:06.979+0000] {local_task_job_runner.py:234} INFO - Task exited with return code 1
[2025-06-06T19:12:07.054+0000] {taskinstance.py:3280} INFO - 0 downstream tasks scheduled from follow-on schedule check
