[2025-06-06T19:10:52.119+0000] {taskinstance.py:1956} INFO - Dependencies all met for dep_context=non-requeueable deps ti=<TaskInstance: parallel_dag.get_users scheduled__2025-06-05T00:00:00+00:00 [queued]>
[2025-06-06T19:10:52.138+0000] {taskinstance.py:1956} INFO - Dependencies all met for dep_context=requeueable deps ti=<TaskInstance: parallel_dag.get_users scheduled__2025-06-05T00:00:00+00:00 [queued]>
[2025-06-06T19:10:52.140+0000] {taskinstance.py:2170} INFO - Starting attempt 1 of 4
[2025-06-06T19:10:52.171+0000] {taskinstance.py:2191} INFO - Executing <Task(PythonOperator): get_users> on 2025-06-05 00:00:00+00:00
[2025-06-06T19:10:52.185+0000] {standard_task_runner.py:60} INFO - Started process 7562 to run task
[2025-06-06T19:10:52.197+0000] {standard_task_runner.py:87} INFO - Running: ['***', 'tasks', 'run', 'parallel_dag', 'get_users', 'scheduled__2025-06-05T00:00:00+00:00', '--job-id', '339', '--raw', '--subdir', 'DAGS_FOLDER/parallel_dag.py', '--cfg-path', '/tmp/tmpuv7h7_ku']
[2025-06-06T19:10:52.204+0000] {standard_task_runner.py:88} INFO - Job 339: Subtask get_users
[2025-06-06T19:10:52.354+0000] {task_command.py:423} INFO - Running <TaskInstance: parallel_dag.get_users scheduled__2025-06-05T00:00:00+00:00 [running]> on host f00d934cb96d
[2025-06-06T19:10:52.526+0000] {taskinstance.py:2480} INFO - Exporting env vars: AIRFLOW_CTX_DAG_OWNER='Pavan Kumar Kodavali' AIRFLOW_CTX_DAG_ID='parallel_dag' AIRFLOW_CTX_TASK_ID='get_users' AIRFLOW_CTX_EXECUTION_DATE='2025-06-05T00:00:00+00:00' AIRFLOW_CTX_TRY_NUMBER='1' AIRFLOW_CTX_DAG_RUN_ID='scheduled__2025-06-05T00:00:00+00:00'
[2025-06-06T19:10:52.530+0000] {taskinstance.py:2698} ERROR - Task failed with exception
Traceback (most recent call last):
  File "/home/airflow/.local/lib/python3.8/site-packages/airflow/models/taskinstance.py", line 433, in _execute_task
    result = execute_callable(context=context, **execute_callable_kwargs)
  File "/home/airflow/.local/lib/python3.8/site-packages/airflow/operators/python.py", line 199, in execute
    return_value = self.execute_callable()
  File "/home/airflow/.local/lib/python3.8/site-packages/airflow/operators/python.py", line 216, in execute_callable
    return self.python_callable(*self.op_args, **self.op_kwargs)
TypeError: get() missing 1 required positional argument: 'url'
[2025-06-06T19:10:52.551+0000] {taskinstance.py:1138} INFO - Marking task as UP_FOR_RETRY. dag_id=parallel_dag, task_id=get_users, execution_date=20250605T000000, start_date=20250606T191052, end_date=20250606T191052
[2025-06-06T19:10:52.598+0000] {standard_task_runner.py:107} ERROR - Failed to execute job 339 for task get_users (get() missing 1 required positional argument: 'url'; 7562)
[2025-06-06T19:10:52.659+0000] {local_task_job_runner.py:234} INFO - Task exited with return code 1
[2025-06-06T19:10:52.699+0000] {taskinstance.py:3280} INFO - 0 downstream tasks scheduled from follow-on schedule check
[2025-06-06T19:12:37.564+0000] {taskinstance.py:1956} INFO - Dependencies all met for dep_context=non-requeueable deps ti=<TaskInstance: parallel_dag.get_users scheduled__2025-06-05T00:00:00+00:00 [queued]>
[2025-06-06T19:12:37.579+0000] {taskinstance.py:1956} INFO - Dependencies all met for dep_context=requeueable deps ti=<TaskInstance: parallel_dag.get_users scheduled__2025-06-05T00:00:00+00:00 [queued]>
[2025-06-06T19:12:37.580+0000] {taskinstance.py:2170} INFO - Starting attempt 1 of 4
[2025-06-06T19:12:37.603+0000] {taskinstance.py:2191} INFO - Executing <Task(PythonOperator): get_users> on 2025-06-05 00:00:00+00:00
[2025-06-06T19:12:37.611+0000] {standard_task_runner.py:60} INFO - Started process 9271 to run task
[2025-06-06T19:12:37.615+0000] {standard_task_runner.py:87} INFO - Running: ['***', 'tasks', 'run', 'parallel_dag', 'get_users', 'scheduled__2025-06-05T00:00:00+00:00', '--job-id', '343', '--raw', '--subdir', 'DAGS_FOLDER/parallel_dag.py', '--cfg-path', '/tmp/tmphyjj0fn5']
[2025-06-06T19:12:37.617+0000] {standard_task_runner.py:88} INFO - Job 343: Subtask get_users
[2025-06-06T19:12:37.732+0000] {task_command.py:423} INFO - Running <TaskInstance: parallel_dag.get_users scheduled__2025-06-05T00:00:00+00:00 [running]> on host f00d934cb96d
[2025-06-06T19:12:37.875+0000] {taskinstance.py:2480} INFO - Exporting env vars: AIRFLOW_CTX_DAG_OWNER='Pavan Kumar Kodavali' AIRFLOW_CTX_DAG_ID='parallel_dag' AIRFLOW_CTX_TASK_ID='get_users' AIRFLOW_CTX_EXECUTION_DATE='2025-06-05T00:00:00+00:00' AIRFLOW_CTX_TRY_NUMBER='1' AIRFLOW_CTX_DAG_RUN_ID='scheduled__2025-06-05T00:00:00+00:00'
[2025-06-06T19:12:37.878+0000] {taskinstance.py:2698} ERROR - Task failed with exception
Traceback (most recent call last):
  File "/home/airflow/.local/lib/python3.8/site-packages/airflow/models/taskinstance.py", line 433, in _execute_task
    result = execute_callable(context=context, **execute_callable_kwargs)
  File "/home/airflow/.local/lib/python3.8/site-packages/airflow/operators/python.py", line 199, in execute
    return_value = self.execute_callable()
  File "/home/airflow/.local/lib/python3.8/site-packages/airflow/operators/python.py", line 216, in execute_callable
    return self.python_callable(*self.op_args, **self.op_kwargs)
TypeError: get() missing 1 required positional argument: 'url'
[2025-06-06T19:12:37.893+0000] {taskinstance.py:1138} INFO - Marking task as UP_FOR_RETRY. dag_id=parallel_dag, task_id=get_users, execution_date=20250605T000000, start_date=20250606T191237, end_date=20250606T191237
[2025-06-06T19:12:37.914+0000] {standard_task_runner.py:107} ERROR - Failed to execute job 343 for task get_users (get() missing 1 required positional argument: 'url'; 9271)
[2025-06-06T19:12:37.953+0000] {local_task_job_runner.py:234} INFO - Task exited with return code 1
[2025-06-06T19:12:38.018+0000] {taskinstance.py:3280} INFO - 0 downstream tasks scheduled from follow-on schedule check
[2025-06-06T19:16:30.719+0000] {taskinstance.py:1956} INFO - Dependencies all met for dep_context=non-requeueable deps ti=<TaskInstance: parallel_dag.get_users scheduled__2025-06-05T00:00:00+00:00 [queued]>
[2025-06-06T19:16:30.739+0000] {taskinstance.py:1956} INFO - Dependencies all met for dep_context=requeueable deps ti=<TaskInstance: parallel_dag.get_users scheduled__2025-06-05T00:00:00+00:00 [queued]>
[2025-06-06T19:16:30.741+0000] {taskinstance.py:2170} INFO - Starting attempt 1 of 4
[2025-06-06T19:16:30.763+0000] {taskinstance.py:2191} INFO - Executing <Task(PythonOperator): get_users> on 2025-06-05 00:00:00+00:00
[2025-06-06T19:16:30.772+0000] {standard_task_runner.py:60} INFO - Started process 13125 to run task
[2025-06-06T19:16:30.782+0000] {standard_task_runner.py:87} INFO - Running: ['***', 'tasks', 'run', 'parallel_dag', 'get_users', 'scheduled__2025-06-05T00:00:00+00:00', '--job-id', '346', '--raw', '--subdir', 'DAGS_FOLDER/parallel_dag.py', '--cfg-path', '/tmp/tmpc3suhb_6']
[2025-06-06T19:16:30.785+0000] {standard_task_runner.py:88} INFO - Job 346: Subtask get_users
[2025-06-06T19:16:31.216+0000] {task_command.py:423} INFO - Running <TaskInstance: parallel_dag.get_users scheduled__2025-06-05T00:00:00+00:00 [running]> on host f00d934cb96d
[2025-06-06T19:16:31.501+0000] {taskinstance.py:2480} INFO - Exporting env vars: AIRFLOW_CTX_DAG_OWNER='Pavan Kumar Kodavali' AIRFLOW_CTX_DAG_ID='parallel_dag' AIRFLOW_CTX_TASK_ID='get_users' AIRFLOW_CTX_EXECUTION_DATE='2025-06-05T00:00:00+00:00' AIRFLOW_CTX_TRY_NUMBER='1' AIRFLOW_CTX_DAG_RUN_ID='scheduled__2025-06-05T00:00:00+00:00'
[2025-06-06T19:16:32.168+0000] {taskinstance.py:2698} ERROR - Task failed with exception
Traceback (most recent call last):
  File "/home/airflow/.local/lib/python3.8/site-packages/airflow/models/taskinstance.py", line 433, in _execute_task
    result = execute_callable(context=context, **execute_callable_kwargs)
  File "/home/airflow/.local/lib/python3.8/site-packages/airflow/operators/python.py", line 199, in execute
    return_value = self.execute_callable()
  File "/home/airflow/.local/lib/python3.8/site-packages/airflow/operators/python.py", line 216, in execute_callable
    return self.python_callable(*self.op_args, **self.op_kwargs)
  File "/opt/airflow/dags/parallel_dag.py", line 20, in get
    with open(f"/opt/airflow/output/{endpoint}_{_now}.json", 'w') as f:
FileNotFoundError: [Errno 2] No such file or directory: '/opt/airflow/output/users_2025--6--6--19--16--31.json'
[2025-06-06T19:16:32.238+0000] {taskinstance.py:1138} INFO - Marking task as UP_FOR_RETRY. dag_id=parallel_dag, task_id=get_users, execution_date=20250605T000000, start_date=20250606T191630, end_date=20250606T191632
[2025-06-06T19:16:32.278+0000] {standard_task_runner.py:107} ERROR - Failed to execute job 346 for task get_users ([Errno 2] No such file or directory: '/opt/airflow/output/users_2025--6--6--19--16--31.json'; 13125)
[2025-06-06T19:16:32.327+0000] {local_task_job_runner.py:234} INFO - Task exited with return code 1
[2025-06-06T19:16:32.364+0000] {taskinstance.py:3280} INFO - 0 downstream tasks scheduled from follow-on schedule check
[2025-06-06T19:19:02.942+0000] {taskinstance.py:1956} INFO - Dependencies all met for dep_context=non-requeueable deps ti=<TaskInstance: parallel_dag.get_users scheduled__2025-06-05T00:00:00+00:00 [queued]>
[2025-06-06T19:19:02.960+0000] {taskinstance.py:1956} INFO - Dependencies all met for dep_context=requeueable deps ti=<TaskInstance: parallel_dag.get_users scheduled__2025-06-05T00:00:00+00:00 [queued]>
[2025-06-06T19:19:02.962+0000] {taskinstance.py:2170} INFO - Starting attempt 1 of 1
[2025-06-06T19:19:02.985+0000] {taskinstance.py:2191} INFO - Executing <Task(PythonOperator): get_users> on 2025-06-05 00:00:00+00:00
[2025-06-06T19:19:02.995+0000] {standard_task_runner.py:60} INFO - Started process 15662 to run task
[2025-06-06T19:19:03.000+0000] {standard_task_runner.py:87} INFO - Running: ['***', 'tasks', 'run', 'parallel_dag', 'get_users', 'scheduled__2025-06-05T00:00:00+00:00', '--job-id', '347', '--raw', '--subdir', 'DAGS_FOLDER/parallel_dag.py', '--cfg-path', '/tmp/tmpv50bvsum']
[2025-06-06T19:19:03.002+0000] {standard_task_runner.py:88} INFO - Job 347: Subtask get_users
[2025-06-06T19:19:03.122+0000] {task_command.py:423} INFO - Running <TaskInstance: parallel_dag.get_users scheduled__2025-06-05T00:00:00+00:00 [running]> on host f00d934cb96d
[2025-06-06T19:19:03.318+0000] {taskinstance.py:2480} INFO - Exporting env vars: AIRFLOW_CTX_DAG_OWNER='Pavan Kumar Kodavali' AIRFLOW_CTX_DAG_ID='parallel_dag' AIRFLOW_CTX_TASK_ID='get_users' AIRFLOW_CTX_EXECUTION_DATE='2025-06-05T00:00:00+00:00' AIRFLOW_CTX_TRY_NUMBER='1' AIRFLOW_CTX_DAG_RUN_ID='scheduled__2025-06-05T00:00:00+00:00'
[2025-06-06T19:19:04.356+0000] {taskinstance.py:2698} ERROR - Task failed with exception
Traceback (most recent call last):
  File "/home/airflow/.local/lib/python3.8/site-packages/airflow/models/taskinstance.py", line 433, in _execute_task
    result = execute_callable(context=context, **execute_callable_kwargs)
  File "/home/airflow/.local/lib/python3.8/site-packages/airflow/operators/python.py", line 199, in execute
    return_value = self.execute_callable()
  File "/home/airflow/.local/lib/python3.8/site-packages/airflow/operators/python.py", line 216, in execute_callable
    return self.python_callable(*self.op_args, **self.op_kwargs)
  File "/opt/airflow/dags/parallel_dag.py", line 20, in get
    with open(f"/opt/airflow/output/{endpoint}_{_now}.json", 'w') as f:
FileNotFoundError: [Errno 2] No such file or directory: '/opt/airflow/output/users_2025--6--6--19--19--3.json'
[2025-06-06T19:19:04.380+0000] {taskinstance.py:1138} INFO - Marking task as FAILED. dag_id=parallel_dag, task_id=get_users, execution_date=20250605T000000, start_date=20250606T191902, end_date=20250606T191904
[2025-06-06T19:19:04.406+0000] {standard_task_runner.py:107} ERROR - Failed to execute job 347 for task get_users ([Errno 2] No such file or directory: '/opt/airflow/output/users_2025--6--6--19--19--3.json'; 15662)
[2025-06-06T19:19:04.425+0000] {local_task_job_runner.py:234} INFO - Task exited with return code 1
[2025-06-06T19:19:04.469+0000] {taskinstance.py:3280} INFO - 0 downstream tasks scheduled from follow-on schedule check
[2025-06-06T19:22:57.552+0000] {taskinstance.py:1956} INFO - Dependencies all met for dep_context=non-requeueable deps ti=<TaskInstance: parallel_dag.get_users scheduled__2025-06-05T00:00:00+00:00 [queued]>
[2025-06-06T19:22:57.570+0000] {taskinstance.py:1956} INFO - Dependencies all met for dep_context=requeueable deps ti=<TaskInstance: parallel_dag.get_users scheduled__2025-06-05T00:00:00+00:00 [queued]>
[2025-06-06T19:22:57.571+0000] {taskinstance.py:2170} INFO - Starting attempt 1 of 1
[2025-06-06T19:22:57.593+0000] {taskinstance.py:2191} INFO - Executing <Task(PythonOperator): get_users> on 2025-06-05 00:00:00+00:00
[2025-06-06T19:22:57.600+0000] {standard_task_runner.py:60} INFO - Started process 19567 to run task
[2025-06-06T19:22:57.618+0000] {standard_task_runner.py:87} INFO - Running: ['***', 'tasks', 'run', 'parallel_dag', 'get_users', 'scheduled__2025-06-05T00:00:00+00:00', '--job-id', '352', '--raw', '--subdir', 'DAGS_FOLDER/parallel_dag.py', '--cfg-path', '/tmp/tmp3dem6g0g']
[2025-06-06T19:22:57.622+0000] {standard_task_runner.py:88} INFO - Job 352: Subtask get_users
[2025-06-06T19:22:57.749+0000] {task_command.py:423} INFO - Running <TaskInstance: parallel_dag.get_users scheduled__2025-06-05T00:00:00+00:00 [running]> on host f00d934cb96d
[2025-06-06T19:22:57.924+0000] {taskinstance.py:2480} INFO - Exporting env vars: AIRFLOW_CTX_DAG_OWNER='Pavan Kumar Kodavali' AIRFLOW_CTX_DAG_ID='parallel_dag' AIRFLOW_CTX_TASK_ID='get_users' AIRFLOW_CTX_EXECUTION_DATE='2025-06-05T00:00:00+00:00' AIRFLOW_CTX_TRY_NUMBER='1' AIRFLOW_CTX_DAG_RUN_ID='scheduled__2025-06-05T00:00:00+00:00'
[2025-06-06T19:22:58.980+0000] {python.py:201} INFO - Done. Returned value was: None
[2025-06-06T19:22:59.019+0000] {taskinstance.py:1138} INFO - Marking task as SUCCESS. dag_id=parallel_dag, task_id=get_users, execution_date=20250605T000000, start_date=20250606T192257, end_date=20250606T192259
[2025-06-06T19:22:59.074+0000] {local_task_job_runner.py:234} INFO - Task exited with return code 0
[2025-06-06T19:22:59.100+0000] {taskinstance.py:3280} INFO - 1 downstream tasks scheduled from follow-on schedule check
