[2025-06-05T16:15:07.743+0000] {taskinstance.py:1956} INFO - Dependencies all met for dep_context=non-requeueable deps ti=<TaskInstance: etl_pipeline_dag.save_datetime scheduled__2025-06-05T16:00:00+00:00 [queued]>
[2025-06-05T16:15:07.754+0000] {taskinstance.py:1956} INFO - Dependencies all met for dep_context=requeueable deps ti=<TaskInstance: etl_pipeline_dag.save_datetime scheduled__2025-06-05T16:00:00+00:00 [queued]>
[2025-06-05T16:15:07.755+0000] {taskinstance.py:2170} INFO - Starting attempt 2 of 4
[2025-06-05T16:15:07.769+0000] {taskinstance.py:2191} INFO - Executing <Task(PythonOperator): save_datetime> on 2025-06-05 16:00:00+00:00
[2025-06-05T16:15:07.776+0000] {standard_task_runner.py:60} INFO - Started process 61920 to run task
[2025-06-05T16:15:07.779+0000] {standard_task_runner.py:87} INFO - Running: ['***', 'tasks', 'run', 'etl_pipeline_dag', 'save_datetime', 'scheduled__2025-06-05T16:00:00+00:00', '--job-id', '106', '--raw', '--subdir', 'DAGS_FOLDER/etl_dag.py', '--cfg-path', '/tmp/tmpo9xs1lp2']
[2025-06-05T16:15:07.782+0000] {standard_task_runner.py:88} INFO - Job 106: Subtask save_datetime
[2025-06-05T16:15:07.875+0000] {task_command.py:423} INFO - Running <TaskInstance: etl_pipeline_dag.save_datetime scheduled__2025-06-05T16:00:00+00:00 [running]> on host 14aa2e8b0b7d
[2025-06-05T16:15:08.270+0000] {taskinstance.py:2480} INFO - Exporting env vars: AIRFLOW_CTX_DAG_OWNER='Pavan Kumar Kodavali' AIRFLOW_CTX_DAG_ID='etl_pipeline_dag' AIRFLOW_CTX_TASK_ID='save_datetime' AIRFLOW_CTX_EXECUTION_DATE='2025-06-05T16:00:00+00:00' AIRFLOW_CTX_TRY_NUMBER='2' AIRFLOW_CTX_DAG_RUN_ID='scheduled__2025-06-05T16:00:00+00:00'
[2025-06-05T16:15:08.309+0000] {taskinstance.py:2698} ERROR - Task failed with exception
Traceback (most recent call last):
  File "/home/airflow/.local/lib/python3.8/site-packages/airflow/models/taskinstance.py", line 433, in _execute_task
    result = execute_callable(context=context, **execute_callable_kwargs)
  File "/home/airflow/.local/lib/python3.8/site-packages/airflow/operators/python.py", line 199, in execute
    return_value = self.execute_callable()
  File "/home/airflow/.local/lib/python3.8/site-packages/airflow/operators/python.py", line 216, in execute_callable
    return self.python_callable(*self.op_args, **self.op_kwargs)
  File "/opt/airflow/dags/etl_dag.py", line 54, in save_datetime
    df.to_csv(csv_path, index=False, mode=df_mode, header=df_header)
  File "/home/airflow/.local/lib/python3.8/site-packages/pandas/core/generic.py", line 3772, in to_csv
    return DataFrameRenderer(formatter).to_csv(
  File "/home/airflow/.local/lib/python3.8/site-packages/pandas/io/formats/format.py", line 1186, in to_csv
    csv_formatter.save()
  File "/home/airflow/.local/lib/python3.8/site-packages/pandas/io/formats/csvs.py", line 240, in save
    with get_handle(
  File "/home/airflow/.local/lib/python3.8/site-packages/pandas/io/common.py", line 859, in get_handle
    handle = open(
PermissionError: [Errno 13] Permission denied: '/tmp/datetimes.csv'
[2025-06-05T16:15:08.330+0000] {taskinstance.py:1138} INFO - Marking task as UP_FOR_RETRY. dag_id=etl_pipeline_dag, task_id=save_datetime, execution_date=20250605T160000, start_date=20250605T161507, end_date=20250605T161508
[2025-06-05T16:15:08.350+0000] {standard_task_runner.py:107} ERROR - Failed to execute job 106 for task save_datetime ([Errno 13] Permission denied: '/tmp/datetimes.csv'; 61920)
[2025-06-05T16:15:08.397+0000] {local_task_job_runner.py:234} INFO - Task exited with return code 1
[2025-06-05T16:15:08.419+0000] {taskinstance.py:3280} INFO - 0 downstream tasks scheduled from follow-on schedule check
